# Error log for fetching data:
 * Debugger PIN: 246-659-906
127.0.0.1 - - [21/Jun/2025 20:22:03] "GET /get_tasks HTTP/1.1" 500 -
Traceback (most recent call last):
  File "D:\Tech_With_Me\todoist\backend\.vnenv\Lib\site-packages\flask\app.py", line 1536, in __call__
    return self.wsgi_app(environ, start_response)
           ~~~~~~~~~~~~~^^^^^^^^^^^^^^^^^^^^^^^^^
  File "D:\Tech_With_Me\todoist\backend\.vnenv\Lib\site-packages\flask\app.py", line 1514, in wsgi_app
    response = self.handle_exception(e)
  File "D:\Tech_With_Me\todoist\backend\.vnenv\Lib\site-packages\flask_cors\extension.py", line 176, in wrapped_function
    return cors_after_request(app.make_response(f(*args, **kwargs)))
                                                ~^^^^^^^^^^^^^^^^^
  File "D:\Tech_With_Me\todoist\backend\.vnenv\Lib\site-packages\flask\app.py", line 1511, in wsgi_app
    response = self.full_dispatch_request()
  File "D:\Tech_With_Me\todoist\backend\.vnenv\Lib\site-packages\flask\app.py", line 919, in full_dispatch_request
    rv = self.handle_user_exception(e)
  File "D:\Tech_With_Me\todoist\backend\.vnenv\Lib\site-packages\flask_cors\extension.py", line 176, in wrapped_function
    return cors_after_request(app.make_response(f(*args, **kwargs)))
                                                ~^^^^^^^^^^^^^^^^^
  File "D:\Tech_With_Me\todoist\backend\.vnenv\Lib\site-packages\flask\app.py", line 917, in full_dispatch_request
    rv = self.dispatch_request()
  File "D:\Tech_With_Me\todoist\backend\.vnenv\Lib\site-packages\flask\app.py", line 902, in dispatch_request
    return self.ensure_sync(self.view_functions[rule.endpoint])(**view_args)  # type: ignore[no-any-return]
           ~~~~~~~~~~~~~~~~~~~~~~~~~~~~~~~~~~~~~~~~~~~~~~~~~~~~^^^^^^^^^^^^^
  File "d:\Tech_With_Me\todoist\backend\src\routes\tasks_routes.py", line 16, in get_tasks
    return tasks_db.get_tasks()
           ~~~~~~~~~~~~~~~~~~^^
  File "d:\Tech_With_Me\todoist\backend\src\services\tasks_service.py", line 23, in get_tasks
    return jsonify({"tasks": tasks}), 200
           ~~~~~~~^^^^^^^^^^^^^^^^^^
  File "D:\Tech_With_Me\todoist\backend\.vnenv\Lib\site-packages\flask\json\__init__.py", line 170, in jsonify
    return current_app.json.response(*args, **kwargs)  # type: ignore[return-value]
           ~~~~~~~~~~~~~~~~~~~~~~~~~^^^^^^^^^^^^^^^^^
  File "D:\Tech_With_Me\todoist\backend\.vnenv\Lib\site-packages\flask\json\provider.py", line 214, in response
    f"{self.dumps(obj, **dump_args)}\n", mimetype=self.mimetype
       ~~~~~~~~~~^^^^^^^^^^^^^^^^^^
  File "D:\Tech_With_Me\todoist\backend\.vnenv\Lib\site-packages\flask\json\provider.py", line 179, in dumps
    return json.dumps(obj, **kwargs)
           ~~~~~~~~~~^^^^^^^^^^^^^^^
  File "D:\python\Lib\json\__init__.py", line 238, in dumps
    **kw).encode(obj)
          ~~~~~~^^^^^
  File "D:\python\Lib\json\encoder.py", line 200, in encode
    chunks = self.iterencode(o, _one_shot=True)
  File "D:\python\Lib\json\encoder.py", line 261, in iterencode
    return _iterencode(o, 0)
  File "D:\Tech_With_Me\todoist\backend\.vnenv\Lib\site-packages\flask\json\provider.py", line 121, in _default
    raise TypeError(f"Object of type {type(o).__name__} is not JSON serializable")
TypeError: Object of type Task is not JSON serializable


Solution: task object was not direclty serializable , so added a to_dict() function in tasks_model